Failure # 1 (occurred at 2021-06-02_15-51-48)
Traceback (most recent call last):
  File "/home/jiekaijia/anaconda3/envs/pytorch/lib/python3.8/site-packages/ray/tune/trial_runner.py", line 702, in _process_trial
    results = self.trial_executor.fetch_result(trial)
  File "/home/jiekaijia/anaconda3/envs/pytorch/lib/python3.8/site-packages/ray/tune/ray_trial_executor.py", line 686, in fetch_result
    result = ray.get(trial_future[0], timeout=DEFAULT_GET_TIMEOUT)
  File "/home/jiekaijia/anaconda3/envs/pytorch/lib/python3.8/site-packages/ray/_private/client_mode_hook.py", line 47, in wrapper
    return func(*args, **kwargs)
  File "/home/jiekaijia/anaconda3/envs/pytorch/lib/python3.8/site-packages/ray/worker.py", line 1481, in get
    raise value.as_instanceof_cause()
ray.exceptions.RayTaskError(AssertionError): [36mray::MADDPG.train_buffered()[39m (pid=23732, ip=192.168.178.102)
  File "python/ray/_raylet.pyx", line 505, in ray._raylet.execute_task
  File "python/ray/_raylet.pyx", line 449, in ray._raylet.execute_task.function_executor
  File "/home/jiekaijia/anaconda3/envs/pytorch/lib/python3.8/site-packages/ray/_private/function_manager.py", line 556, in actor_method_executor
    return method(__ray_actor, *args, **kwargs)
  File "/home/jiekaijia/anaconda3/envs/pytorch/lib/python3.8/site-packages/ray/tune/trainable.py", line 173, in train_buffered
    result = self.train()
  File "/home/jiekaijia/anaconda3/envs/pytorch/lib/python3.8/site-packages/ray/rllib/agents/trainer.py", line 573, in train
    raise e
  File "/home/jiekaijia/anaconda3/envs/pytorch/lib/python3.8/site-packages/ray/rllib/agents/trainer.py", line 562, in train
    result = Trainable.train(self)
  File "/home/jiekaijia/anaconda3/envs/pytorch/lib/python3.8/site-packages/ray/tune/trainable.py", line 232, in train
    result = self.step()
  File "/home/jiekaijia/anaconda3/envs/pytorch/lib/python3.8/site-packages/ray/rllib/agents/trainer_template.py", line 162, in step
    res = next(self.train_exec_impl)
  File "/home/jiekaijia/anaconda3/envs/pytorch/lib/python3.8/site-packages/ray/util/iter.py", line 756, in __next__
    return next(self.built_iterator)
  File "/home/jiekaijia/anaconda3/envs/pytorch/lib/python3.8/site-packages/ray/util/iter.py", line 783, in apply_foreach
    for item in it:
  File "/home/jiekaijia/anaconda3/envs/pytorch/lib/python3.8/site-packages/ray/util/iter.py", line 843, in apply_filter
    for item in it:
  File "/home/jiekaijia/anaconda3/envs/pytorch/lib/python3.8/site-packages/ray/util/iter.py", line 843, in apply_filter
    for item in it:
  File "/home/jiekaijia/anaconda3/envs/pytorch/lib/python3.8/site-packages/ray/util/iter.py", line 783, in apply_foreach
    for item in it:
  File "/home/jiekaijia/anaconda3/envs/pytorch/lib/python3.8/site-packages/ray/util/iter.py", line 843, in apply_filter
    for item in it:
  File "/home/jiekaijia/anaconda3/envs/pytorch/lib/python3.8/site-packages/ray/util/iter.py", line 1075, in build_union
    item = next(it)
  File "/home/jiekaijia/anaconda3/envs/pytorch/lib/python3.8/site-packages/ray/util/iter.py", line 756, in __next__
    return next(self.built_iterator)
  File "/home/jiekaijia/anaconda3/envs/pytorch/lib/python3.8/site-packages/ray/util/iter.py", line 783, in apply_foreach
    for item in it:
  File "/home/jiekaijia/anaconda3/envs/pytorch/lib/python3.8/site-packages/ray/util/iter.py", line 783, in apply_foreach
    for item in it:
  File "/home/jiekaijia/anaconda3/envs/pytorch/lib/python3.8/site-packages/ray/util/iter.py", line 783, in apply_foreach
    for item in it:
  [Previous line repeated 1 more time]
  File "/home/jiekaijia/anaconda3/envs/pytorch/lib/python3.8/site-packages/ray/util/iter.py", line 471, in base_iterator
    yield ray.get(futures, timeout=timeout)
  File "/home/jiekaijia/anaconda3/envs/pytorch/lib/python3.8/site-packages/ray/_private/client_mode_hook.py", line 47, in wrapper
    return func(*args, **kwargs)
ray.exceptions.RayTaskError(AssertionError): [36mray::RolloutWorker.par_iter_next()[39m (pid=23729, ip=192.168.178.102)
  File "python/ray/_raylet.pyx", line 505, in ray._raylet.execute_task
  File "python/ray/_raylet.pyx", line 449, in ray._raylet.execute_task.function_executor
  File "/home/jiekaijia/anaconda3/envs/pytorch/lib/python3.8/site-packages/ray/_private/function_manager.py", line 556, in actor_method_executor
    return method(__ray_actor, *args, **kwargs)
  File "/home/jiekaijia/anaconda3/envs/pytorch/lib/python3.8/site-packages/ray/util/iter.py", line 1152, in par_iter_next
    return next(self.local_it)
  File "/home/jiekaijia/anaconda3/envs/pytorch/lib/python3.8/site-packages/ray/rllib/evaluation/rollout_worker.py", line 332, in gen_rollouts
    yield self.sample()
  File "/home/jiekaijia/anaconda3/envs/pytorch/lib/python3.8/site-packages/ray/rllib/evaluation/rollout_worker.py", line 707, in sample
    batches = [self.input_reader.next()]
  File "/home/jiekaijia/anaconda3/envs/pytorch/lib/python3.8/site-packages/ray/rllib/evaluation/sampler.py", line 96, in next
    batches = [self.get_data()]
  File "/home/jiekaijia/anaconda3/envs/pytorch/lib/python3.8/site-packages/ray/rllib/evaluation/sampler.py", line 223, in get_data
    item = next(self.rollout_provider)
  File "/home/jiekaijia/anaconda3/envs/pytorch/lib/python3.8/site-packages/ray/rllib/evaluation/sampler.py", line 648, in _env_runner
    base_env.send_actions(actions_to_send)
  File "/home/jiekaijia/anaconda3/envs/pytorch/lib/python3.8/site-packages/ray/rllib/env/base_env.py", line 421, in send_actions
    obs, rewards, dones, infos = env.step(agent_dict)
  File "/home/jiekaijia/anaconda3/envs/pytorch/lib/python3.8/site-packages/ray/rllib/env/wrappers/pettingzoo_env.py", line 174, in step
    obss, rews, dones, infos = self.par_env.step(action_dict)
  File "/home/jiekaijia/anaconda3/envs/pytorch/lib/python3.8/site-packages/pettingzoo/utils/conversions.py", line 72, in step
    self.aec_env.step(actions[agent])
  File "/home/jiekaijia/anaconda3/envs/pytorch/lib/python3.8/site-packages/pettingzoo/utils/wrappers/order_enforcing.py", line 56, in step
    super().step(action)
  File "/home/jiekaijia/anaconda3/envs/pytorch/lib/python3.8/site-packages/pettingzoo/utils/wrappers/base.py", line 68, in step
    self.env.step(action)
  File "/home/jiekaijia/anaconda3/envs/pytorch/lib/python3.8/site-packages/pettingzoo/utils/wrappers/assert_out_of_bounds.py", line 15, in step
    assert (action is None and self.dones[self.agent_selection]) or self.action_spaces[self.agent_selection].contains(action), "action is not in action space"
AssertionError: action is not in action space

